Workbook
Name _1: #REF!
Name _1: #REF!
Name _1: #REF!
Name _1: #REF!
Name _1: #REF!
Name _1: #REF!
Name _1: #REF!
Name _1: #REF!
Name _1: #REF!
Name _1: #REF!
Name _1: #REF!
Name _1: #REF!
Name _1: #REF!
Name _10: #REF!
Name _10: #REF!
Name _10: #REF!
Name _10: #REF!
Name _10: #REF!
Name _10: #REF!
Name _10: #REF!
Name _10: #REF!
Name _10: #REF!
Name _10: #REF!
Name _10: #REF!
Name _10: #REF!
Name _10: #REF!
Name _11: #REF!
Name _11: #REF!
Name _11: #REF!
Name _11: #REF!
Name _11: #REF!
Name _11: #REF!
Name _11: #REF!
Name _11: #REF!
Name _11: #REF!
Name _11: #REF!
Name _11: #REF!
Name _11: #REF!
Name _11: #REF!
Name _12: #REF!
Name _12: #REF!
Name _12: #REF!
Name _12: #REF!
Name _12: #REF!
Name _12: #REF!
Name _12: #REF!
Name _12: #REF!
Name _12: #REF!
Name _12: #REF!
Name _12: #REF!
Name _12: #REF!
Name _12: #REF!
Name _13: #REF!
Name _13: #REF!
Name _13: #REF!
Name _13: #REF!
Name _13: #REF!
Name _13: #REF!
Name _13: #REF!
Name _13: #REF!

Sheet Grand Summary
A2: THE GOVERNMENT OF THE HONG KONG SPECIAL ADMINISTRATIVE REGION
A4: HIGHWAYS DEPARTMENT
A5: MAJOR WORKS PROJECT MANAGEMENT OFFICE
A7: CONTRACT NO. HY/2022/14
A8: MODIFICATION WORKS OF NOISE BARRIERS ALONG YUEN LONG HIGHWAY NEAR PARK SIGNATURE
A10: GRAND SUMMARY OF
A11: THE ACTIVITY SCHEDULE
A13: Page | B13: Description | J13: Amount (HK$)
A14: AS.S1/16 | C14: Schedule No. 1 - Preliminaries | J14: $
A15: AS.S2/01 | C15: Schedule No. 2 - Preservation and Protection of Trees | J15: $
A16: AS.S3/05 | C16: Schedule No. 3 - Modification Works of Noise Barriers | J16: $
A17: AS.S4/03 | C17: Schedule No. 4 - Monitoring Payment of Wages | J17: $
A18: AS.S5/10 | C18: Schedule No. 5 - Site Safety | J18: $ | K18: ='A5'!K630 -> 252780
A19: AS.S6/03 | C19: Schedule No. 6 - Site Cleanliness and Tidiness | J19: $ | K19: ='A6'!K204 -> 419322
C42: Sub-total of above (A) | J42: $
C43: Tendered total of the Prices = (A) [To be carried to the Form of Tender and the Contract Data Part two subject to the correction rules for tender errors as set out in Clause GCT 11 of the General Conditions of Tender] | J43: $
C44: Contingency sum for Defined Cost for compensation events* (B) | J44: $ | K44: 2100000
C45: Contingency sum for Fee for compensation events* (C) = (B) x fee percentage inserted by the tenderer in the Contract Data Part two | J45: $
C46: Provisional sum for price adjustment for inflation under Secondary Option X1* (D) | J46: $ | K46: 945000
C47: Provisional sum for performance‐tied payment item under Pay for Safety Performance Merit Scheme (PFSPMS) under Secondary Option X20* (E) | J47: $ | K47: 336188
C48: Sub‐total of all contingency sums and provisional sums above* (F) = (B) + (C) + (D) + (E)
C49: Forecast total of the Prices for tender evaluation purpose* (G) = (A) + (F) | J49: To be completed by the Project Manager designate after receipt of tender
A51: *Remarks: The contingency sums, provisional sums and forecast total of the Prices shall not form part of this contract. Please refer to Clause [A7] of the additional conditions of contract.
A52: (1) The contingency sums, provisional sums and forecast total of the Prices shall not form part of the contract. Please refer to Clause A7 of the additional conditions of contract.
B55: Signature of person authorised
B56: to sign on behalf of tenderer : | G56: ……………………………………………………
B58: Name of Tenderer: | G58: ……………………………………………………
B60: Date: | G60: ……………………………………………………
A63: [BLANK PAGE]

Sheet A1
A2: THE GOVERNMENT OF THE HONG KONG SPECIAL ADMINISTRATIVE REGION
A4: HIGHWAYS DEPARTMENT
A5: MAJOR WORKS PROJECT MANAGEMENT OFFICE
A7: ='Grand Summary'!A7:K7 -> CONTRACT NO. HY/2022/14
A8: ='Grand Summary'!A8:K8 -> MODIFICATION WORKS OF NOISE BARRIERS ALONG YUEN LONG HIGHWAY NEAR PARK SIGNATURE
A10: ACTIVITY SCHEDULE
A12: Schedule No. 1 - Preliminaries
A14: Item | B14: Activity | J14: Prices (HK$)
A16: 1.1 | B16: Temporary Accommodation for the Project Manager and Supervisor
A18: 1.1.1 | B18: Provision of the temporary accommodation for the Project Manager and Supervisor to the satisfaction of the Project Manager | J18: $
A21: 1.1.2 | B21: Provision of all furniture required by this contract to enable operation | J21: $
A23: 1.1.3.1 | B23: Fulfilling the obligations of maintenance of temporary accommodation provided for the 1st calendar month | J23: $
A24: 1.1.3.2 | B24: Fulfilling the obligations of maintenance of temporary accommodation provided for the 2nd calendar month | J24: $
A25: 1.1.3.3 | B25: Fulfilling the obligations of maintenance of temporary accommodation provided for the 3rd calendar month | J25: $
A26: 1.1.3.4 | B26: Fulfilling the obligations of maintenance of temporary accommodation provided for the 4th calendar month | J26: $
A27: 1.1.3.5 | B27: Fulfilling the obligations of maintenance of temporary accommodation provided for the 5th calendar month | J27: $
A28: 1.1.3.6 | B28: Fulfilling the obligations of maintenance of temporary accommodation provided for the 6th calendar month | J28: $
A29: 1.1.3.7 | B29: Fulfilling the obligations of maintenance of temporary accommodation provided for the 7th calendar month | J29: $
A30: 1.1.3.8 | B30: Fulfilling the obligations of maintenance of temporary accommodation provided for the 8th calendar month | J30: $
A31: 1.1.3.9 | B31: Fulfilling the obligations of maintenance of temporary accommodation provided for the 9th calendar month | J31: $
A32: 1.1.3.10 | B32: Fulfilling the obligations of maintenance of temporary accommodation provided for the 10th calendar month | J32: $
... A48: 1.1.4 | B48: Demolition, clear and reinstatement of the area occupied by temporary accommodation and handover to the Client | J48: $
I80: Total carried to collection | J80: $
A81: Item | B81: Activity | J81: Prices (HK$)
A83: 1.2 | B83: Temporary Accommodation for the Contractor
A85: 1.2.1 | B85: Provision of the temporary accommodation including workshops, offices, storage sheds and security system for the Contractor to the satisfaction of the Project Manager | J85: $
A88: 1.2.2 | B88: Provision of all furniture required by this contract to enable operation | J88: $
A90: 1.2.3.1 | B90: Fulfilling the obligations of servicing of the Contractor's temporary accommodation for the 1st calendar month | J90: $
A91: 1.2.3.2 | B91: Fulfilling the obligations of servicing of the Contractor's temporary accommodation for the 2nd calendar month | J91: $
A92: 1.2.3.3 | B92: Fulfilling the obligations of servicing of the Contractor's temporary accommodation for the 3rd calendar month | J92: $
A93: 1.2.3.4 | B93: Fulfilling the obligations of servicing of the Contractor's temporary accommodation for the 4th calendar month | J93: $
A94: 1.2.3.5 | B94: Fulfilling the obligations of servicing of the Contractor's temporary accommodation for the 5th calendar month | J94: $
A95: 1.2.3.6 | B95: Fulfilling the obligations of servicing of the Contractor's temporary accommodation for the 6th calendar month | J95: $
A96: 1.2.3.7 | B96: Fulfilling the obligations of servicing of the Contractor's temporary accommodation for the 7th calendar month | J96: $
A97: 1.2.3.8 | B97: Fulfilling the obligations of servicing of the Contractor's temporary accommodation for the 8th calendar month | J97: $
A98: 1.2.3.9 | B98: Fulfilling the obligations of servicing of the Contractor's temporary accommodation for the 9th calendar month | J98: $
A99: 1.2.3.10 | B99: Fulfilling the obligations of servicing of the Contractor's temporary accommodation for the 10th calendar month | J99: $
... A115: 1.2.4 | B115: Demolition, clear and reinstatement of the area occupied by temporary accommodation and handover to the Client | J115: $
I150: Total carried to collection | J150: $
A151: Item | B151: Activity | J151: Prices (HK$)
...

Sheet A2
A2: THE GOVERNMENT OF THE HONG KONG SPECIAL ADMINISTRATIVE REGION
A4: HIGHWAYS DEPARTMENT
A5: MAJOR WORKS PROJECT MANAGEMENT OFFICE
A7: ='Grand Summary'!A7:K7 -> CONTRACT NO. HY/2022/14
A8: ='Grand Summary'!A8:K8 -> MODIFICATION WORKS OF NOISE BARRIERS ALONG YUEN LONG HIGHWAY NEAR PARK SIGNATURE
A10: ACTIVITY SCHEDULE
A12: Schedule No. 2 - Preservation and Protection of Trees
A14: Item | B14: Activity | J14: Prices (HK$)
A16: 2 | B16: Preservation and Protection of Trees
A18: 2.1 | B18: Preservation and protection measures to the preserved trees
A20: 2.1.1 | B20: Fulfilling the obligations of preservation and protection measures to the preserved trees for the 1st calender month | J20: $
A21: 2.1.2 | B21: Fulfilling the obligations of preservation and protection measures to the preserved trees for the 2nd calender month | J21: $
A22: 2.1.3 | B22: Fulfilling the obligations of preservation and protection measures to the preserved trees for the 3rd calender month | J22: $
A23: 2.1.4 | B23: Fulfilling the obligations of preservation and protection measures to the preserved trees for the 4th calender month | J23: $
A24: 2.1.5 | B24: Fulfilling the obligations of preservation and protection measures to the preserved trees for the 5th calender month | J24: $
A25: 2.1.6 | B25: Fulfilling the obligations of preservation and protection measures to the preserved trees for the 6th calender month | J25: $
A26: 2.1.7 | B26: Fulfilling the obligations of preservation and protection measures to the preserved trees for the 7th calender month | J26: $
A27: 2.1.8 | B27: Fulfilling the obligations of preservation and protection measures to the preserved trees for the 8th calender month | J27: $
A28: 2.1.9 | B28: Fulfilling the obligations of preservation and protection measures to the preserved trees for the 9th calender month | J28: $
A29: 2.1.10 | B29: Fulfilling the obligations of preservation and protection measures to the preserved trees for the 10th calender month | J29: $
A30: 2.1.11 | B30: Fulfilling the obligations of preservation and protection measures to the preserved trees for the 11th calender month | J30: $
A31: 2.1.12 | B31: Fulfilling the obligations of preservation and protection measures to the preserved trees for the 12th calender month | J31: $
... A43: 2.1.24 | B43: Fulfilling the obligations of preservation and protection measures to the preserved trees for the 24th calender month | J43: $
A45: 2.2 | B45: Tree survey of existing trees and Report on updating of photographical records | J45: $
A47: 2.3 | B47: Tree risk assessment | J47: $
A49: 2.4 | B49: Additional items required by the Contractor (to be inserted by the Contractor) | J49: $
I71: Total Prices of Schedule No. 2 Carried to Grand Summary of the Activity Schedule | J71: $
A72: Item | B72: Activity | J72: Prices (HK$)
B74: Collection from Page AS.S4/1 | J74: $
I133: Total Prices of Schedule No. 4 Carried to Grand Summary of the Activity Schedule | J133: $

Sheet A3
A2: THE GOVERNMENT OF THE HONG KONG SPECIAL ADMINISTRATIVE REGION
A4: HIGHWAYS DEPARTMENT
A5: MAJOR WORKS PROJECT MANAGEMENT OFFICE
A7: ='Grand Summary'!A7:K7 -> CONTRACT NO. HY/2022/14
A8: ='Grand Summary'!A8:K8 -> MODIFICATION WORKS OF NOISE BARRIERS ALONG YUEN LONG HIGHWAY NEAR PARK SIGNATURE
A10: ACTIVITY SCHEDULE
A12: Schedule No. 3 - Modification Works of Noise Barriers
A14: Item | B14: Activity | J14: Prices (HK$)
A16: 3 | B16: Modification Works of Noise Barriers
A18: 3.1 | B18: Dismantling and disposal of existing steel posts, sub-frames, base plates and other accessories of noise barriers
A20: 3.1.1 | B20: Completion of dismantling and disposal of existing vertical posts, sub-frames, base plates and other accessories | J20: $
B21: of noise barriers for Bay A1
A22: 3.1.2 | B22: Completion of dismantling and disposal of existing vertical posts, sub-frames, base plates and other accessories | J22: $
B23: of noise barriers for Bay B1
A24: 3.1.3 | B24: Completion of dismantling and disposal of existing vertical posts, sub-frames, base plates and other accessories | J24: $
B25: of noise barriers for Bay B2
A26: 3.1.4 | B26: Completion of dismantling and disposal of existing vertical posts, sub-frames, base plates and other accessories | J26: $
B27: of noise barriers for Bay B3
A28: 3.1.5 | B28: Completion of dismantling and disposal of existing vertical posts, sub-frames, base plates and other accessories | J28: $
B29: of noise barriers for Bay B4
A30: 3.1.6 | B30: Completion of dismantling and disposal of existing vertical posts, sub-frames, base plates and other accessories | J30: $
B31: of noise barriers for Bay B5
A32: 3.1.7 | B32: Completion of dismantling and disposal of existing vertical posts, sub-frames, base plates and other accessories | J32: $
B33: of noise barriers for Bay C1
A34: 3.1.8 | B34: Completion of dismantling and disposal of existing vertical posts, sub-frames, base plates and other accessories | J34: $
B35: of noise barriers for Bay C2
A36: 3.1.9 | B36: Completion of dismantling and disposal of existing vertical posts, sub-frames, base plates and other accessories | J36: $
B37: of noise barriers for Bay C3
A38: 3.1.10 | B38: Completion of dismantling and disposal of existing vertical posts, sub-frames, base plates and other accessories | J38: $
B39: of noise barriers for Bay C4
A40: 3.1.11 | B40: Completion of dismantling and disposal of existing vertical posts, sub-frames, base plates and other accessories | J40: $
B41: of noise barriers for Bay C5
A43: 3.2 | B43: Installation of new vertical posts and base plates of noise barriers
A45: 3.2.1 | B45: Completion of installation of new vertical posts and base plates of noise barriers for Bay A1 | J45: $
A46: 3.2.2 | B46: Completion of installation of new vertical posts and base plates of noise barriers for Bay B1 | J46: $
A47: 3.2.3 | B47: Completion of installation of new vertical posts and base plates of noise barriers for Bay B2 | J47: $
A48: 3.2.4 | B48: Completion of installation of new vertical posts and base plates of noise barriers for Bay B3 | J48: $
A49: 3.2.5 | B49: Completion of installation of new vertical posts and base plates of noise barriers for Bay B4 | J49: $
A50: 3.2.6 | B50: Completion of installation of new vertical posts and base plates of noise barriers for Bay B5 | J50: $
A51: 3.2.7 | B51: Completion of installation of new vertical posts and base plates of noise barriers for Bay C1 | J51: $
...

Sheet A4
A2: THE GOVERNMENT OF THE HONG KONG SPECIAL ADMINISTRATIVE REGION
A4: HIGHWAYS DEPARTMENT
A5: MAJOR WORKS PROJECT MANAGEMENT OFFICE
A7: ='Grand Summary'!A7:K7 -> CONTRACT NO. HY/2022/14
A8: ='Grand Summary'!A8:K8 -> MODIFICATION WORKS OF NOISE BARRIERS ALONG YUEN LONG HIGHWAY NEAR PARK SIGNATURE
A10: ACTIVITY SCHEDULE
A12: Schedule No. 4 - Monitoring Payment of Wages
A14: Item | B14: Activity | J14: Prices (HK$)
A16: 4 | B16: Monitoring Payment of Wages
A18: 4.1 | B18: Completion of establishment monitoring system for payment of wages | J18: $
A20: 4.2.1 | B20: Fulfilling the obligations of operating the monitoring system of payment of wages for the 1st calendar month | J20: $ | K20: 9000
A21: 4.2.2 | B21: Fulfilling the obligations of operating the monitoring system of payment of wages for the 2nd calendar month | J21: $ | K21: 9000
A22: 4.2.3 | B22: Fulfilling the obligations of operating the monitoring system of payment of wages for the 3rd calendar month | J22: $ | K22: 9000
A23: 4.2.4 | B23: Fulfilling the obligations of operating the monitoring system of payment of wages for the 4th calendar month | J23: $ | K23: 9000
A24: 4.2.5 | B24: Fulfilling the obligations of operating the monitoring system of payment of wages for the 5th calendar month | J24: $ | K24: 9000
A25: 4.2.6 | B25: Fulfilling the obligations of operating the monitoring system of payment of wages for the 6th calendar month | J25: $ | K25: 9000
A26: 4.2.7 | B26: Fulfilling the obligations of operating the monitoring system of payment of wages for the 7th calendar month | J26: $ | K26: 9000
A27: 4.2.8 | B27: Fulfilling the obligations of operating the monitoring system of payment of wages for the 8th calendar month | J27: $ | K27: 9000
A28: 4.2.9 | B28: Fulfilling the obligations of operating the monitoring system of payment of wages for the 9th calendar month | J28: $ | K28: 9000
A29: 4.2.10 | B29: Fulfilling the obligations of operating the monitoring system of payment of wages for the 10th calendar month | J29: $ | K29: 9000
A30: 4.2.11 | B30: Fulfilling the obligations of operating the monitoring system of payment of wages for the 11th calendar month | J30: $ | K30: 9000
A31: 4.2.12 | B31: Fulfilling the obligations of operating the monitoring system of payment of wages for the 12th calendar month | J31: $ | K31: 9000
... A43: 4.2.24 | B43: Fulfilling the obligations of operating the monitoring system of payment of wages for the 24th calendar month | J43: $ | K43: 9000
I71: Total carried to collection | J71: $
A72: Item | B72: Activity | J72: Prices (HK$)
A74: 4.3 | B74: Contractor's Labour Officer
A76: 4.3.1 | B76: Provision of Contractor's Labour Officer for the 1st calendar month | J76: $
A77: 4.3.2 | B77: Provision of Contractor's Labour Officer for the 2nd calendar month | J77: $
A78: 4.3.3 | B78: Provision of Contractor's Labour Officer for the 3rd calendar month | J78: $
A79: 4.3.4 | B79: Provision of Contractor's Labour Officer for the 4th calendar month | J79: $
A80: 4.3.5 | B80: Provision of Contractor's Labour Officer for the 5th calendar month | J80: $
A81: 4.3.6 | B81: Provision of Contractor's Labour Officer for the 6th calendar month | J81: $
A82: 4.3.7 | B82: Provision of Contractor's Labour Officer for the 7th calendar month | J82: $
A83: 4.3.8 | B83: Provision of Contractor's Labour Officer for the 8th calendar month | J83: $
A84: 4.3.9 | B84: Provision of Contractor's Labour Officer for the 9th calendar month | J84: $
A85: 4.3.10 | B85: Provision of Contractor's Labour Officer for the 10th calendar month | J85: $
A86: 4.3.11 | B86: Provision of Contractor's Labour Officer for the 11th calendar month | J86: $
A87: 4.3.12 | B87: Provision of Contractor's Labour Officer for the 12th calendar month | J87: $
... A99: 4.3.24 | B99: Provision of Contractor's Labour Officer for the 24th calendar month | J99: $
I129: Total carried to collection | J129: $
...

Sheet A5
A2: THE GOVERNMENT OF THE HONG KONG SPECIAL ADMINISTRATIVE REGION
A4: HIGHWAYS DEPARTMENT
A5: MAJOR WORKS PROJECT MANAGEMENT OFFICE
A7: ='Grand Summary'!A7:K7 -> CONTRACT NO. HY/2022/14
A8: ='Grand Summary'!A8:K8 -> MODIFICATION WORKS OF NOISE BARRIERS ALONG YUEN LONG HIGHWAY NEAR PARK SIGNATURE
A10: ACTIVITY SCHEDULE
A12: Schedule No. 5 - Site Safety
A14: Item | B14: Activity | J14: Prices (HK$)
A16: 5 | B16: Site Safety
A18: 5.1.1 | B18: Provide Safety Officer for the 1st calendar month | J18: $ | K18: 1800
A19: 5.1.2 | B19: Provide Safety Officer for the 2nd calendar month | J19: $ | K19: 1800
A20: 5.1.3 | B20: Provide Safety Officer for the 3rd calendar month | J20: $ | K20: 1800
A21: 5.1.4 | B21: Provide Safety Officer for the 4th calendar month | J21: $ | K21: 1800
A22: 5.1.5 | B22: Provide Safety Officer for the 5th calendar month | J22: $ | K22: 1800
A23: 5.1.6 | B23: Provide Safety Officer for the 6th calendar month | J23: $ | K23: 1800
A24: 5.1.7 | B24: Provide Safety Officer for the 7th calendar month | J24: $ | K24: 1800
A25: 5.1.8 | B25: Provide Safety Officer for the 8th calendar month | J25: $ | K25: 1800
A26: 5.1.9 | B26: Provide Safety Officer for the 9th calendar month | J26: $ | K26: 1800
A27: 5.1.10 | B27: Provide Safety Officer for the 10th calendar month | J27: $ | K27: 1800
A28: 5.1.11 | B28: Provide Safety Officer for the 11th calendar month | J28: $ | K28: 1800
A29: 5.1.12 | B29: Provide Safety Officer for the 12th calendar month | J29: $ | K29: 1800
... A41: 5.1.24 | B41: Provide Safety Officer for the 24th calendar month | J41: $ | K41: 1800
I72: Total carried to collection | J72: $ | K72: =SUM(K18:K70) -> 43200
A73: Item | B73: Activity | J73: Prices (HK$)
A75: 5.2.1 | B75: Attend Site Safety Meeting Committee for the 1st calendar month | J75: $ | K75: 445
A76: 5.2.2 | B76: Attend Site Safety Meeting Committee for the 2nd calendar month | J76: $ | K76: 445
A77: 5.2.3 | B77: Attend Site Safety Meeting Committee for the 3rd calendar month | J77: $ | K77: 445
A78: 5.2.4 | B78: Attend Site Safety Meeting Committee for the 4th calendar month | J78: $ | K78: 445
A79: 5.2.5 | B79: Attend Site Safety Meeting Committee for the 5th calendar month | J79: $ | K79: 445
A80: 5.2.6 | B80: Attend Site Safety Meeting Committee for the 6th calendar month | J80: $ | K80: 445
A81: 5.2.7 | B81: Attend Site Safety Meeting Committee for the 7th calendar month | J81: $ | K81: 445
A82: 5.2.8 | B82: Attend Site Safety Meeting Committee for the 8th calendar month | J82: $ | K82: 445
A83: 5.2.9 | B83: Attend Site Safety Meeting Committee for the 9th calendar month | J83: $ | K83: 445
A84: 5.2.10 | B84: Attend Site Safety Meeting Committee for the 10th calendar month | J84: $ | K84: 445
A85: 5.2.11 | B85: Attend Site Safety Meeting Committee for the 11th calendar month | J85: $ | K85: 445
A86: 5.2.12 | B86: Attend Site Safety Meeting Committee for the 12th calendar month | J86: $ | K86: 445
... A98: 5.2.24 | B98: Attend Site Safety Meeting Committee for the 24th calendar month | J98: $ | K98: 445
I135: Total carried to collection | J135: $ | K135: =SUM(K75:K133) -> 10680
A136: Item | B136: Activity | J136: Prices (HK$)
A138: 5.3.1 | B138: Attend Site Safety Committee for the 1st calendar month | J138: $ | K138: 445
...

Sheet A6
A2: THE GOVERNMENT OF THE HONG KONG SPECIAL ADMINISTRATIVE REGION
A4: HIGHWAYS DEPARTMENT
A5: MAJOR WORKS PROJECT MANAGEMENT OFFICE
A7: ='Grand Summary'!A7:K7 -> CONTRACT NO. HY/2022/14
A8: ='Grand Summary'!A8:K8 -> MODIFICATION WORKS OF NOISE BARRIERS ALONG YUEN LONG HIGHWAY NEAR PARK SIGNATURE
A10: ACTIVITY SCHEDULE
A12: Schedule No. 6 - Site Cleanliness and Tidiness
A14: Item | B14: Activity | J14: Prices (HK$)
A16: 6 | B16: Site Cleanliness and Tidiness
A18: 6.1.1 | B18: Completion of daily cleaning for the 1st calendar month | J18: $ | K18: 20333
A19: 6.1.2 | B19: Completion of daily cleaning for the 2nd calendar month | J19: $ | K19: 20333
A20: 6.1.3 | B20: Completion of daily cleaning for the 3rd calendar month | J20: $ | K20: 20333
A21: 6.1.4 | B21: Completion of daily cleaning for the 4th calendar month | J21: $ | K21: 20333
A22: 6.1.5 | B22: Completion of daily cleaning for the 5th calendar month | J22: $ | K22: 20333
A23: 6.1.6 | B23: Completion of daily cleaning for the 6th calendar month | J23: $ | K23: 20333
A24: 6.1.7 | B24: Completion of daily cleaning for the 7th calendar month | J24: $ | K24: 20333
A25: 6.1.8 | B25: Completion of daily cleaning for the 8th calendar month | J25: $ | K25: 20333
A26: 6.1.9 | B26: Completion of daily cleaning for the 9th calendar month | J26: $ | K26: 20333
A27: 6.1.10 | B27: Completion of daily cleaning for the 10th calendar month | J27: $ | K27: 20333
A28: 6.1.11 | B28: Completion of daily cleaning for the 11th calendar month | J28: $ | K28: 20333
A29: 6.1.12 | B29: Completion of daily cleaning for the 12th calendar month | J29: $ | K29: 20333
... A34: 6.1.17 | B34: Completion of daily cleaning for the 17th-24th calendar months | J34: $ | K34: 20333
I76: Total carried to collection | J76: $ | K76: =SUM(K18:K75) -> 345661
A77: Item | B77: Activity | J77: Prices (HK$)
A79: 6.2.1 | B79: Completion of weekly tidying for the 1st calendar month | J79: $ | K79: 4333
A80: 6.2.2 | B80: Completion of weekly tidying for the 2nd calendar month | J80: $ | K80: 4333
A81: 6.2.3 | B81: Completion of weekly tidying for the 3rd calendar month | J81: $ | K81: 4333
A82: 6.2.4 | B82: Completion of weekly tidying for the 4th calendar month | J82: $ | K82: 4333
A83: 6.2.5 | B83: Completion of weekly tidying for the 5th calendar month | J83: $ | K83: 4333
A84: 6.2.6 | B84: Completion of weekly tidying for the 6th calendar month | J84: $ | K84: 4333
A85: 6.2.7 | B85: Completion of weekly tidying for the 7th calendar month | J85: $ | K85: 4333
A86: 6.2.8 | B86: Completion of weekly tidying for the 8th calendar month | J86: $ | K86: 4333
A87: 6.2.9 | B87: Completion of weekly tidying for the 9th calendar month | J87: $ | K87: 4333
A88: 6.2.10 | B88: Completion of weekly tidying for the 10th calendar month | J88: $ | K88: 4333
A89: 6.2.11 | B89: Completion of weekly tidying for the 11th calendar month | J89: $ | K89: 4333
A90: 6.2.12 | B90: Completion of weekly tidying for the 12th calendar month | J90: $ | K90: 4333
... A95: 6.2.17 | B95: Completion of weekly tidying for the 17th-24th calendar months | J95: $ | K95: 4333
I140: Total carried to collection | J140: $ | K140: =SUM(K79:K139) -> 73661
A141: Item | B141: Activity | J141: Prices (HK$)
B143: Collection from Page AS.S6/1 | J143: $ | K143: =K76 -> 345661
...

Sheet A13
A2: THE GOVERNMENT OF THE HONG KONG SPECIAL ADMINISTRATIVE REGION
A4: HIGHWAYS DEPARTMENT
A5: MAJOR WORKS PROJECT MANAGEMENT OFFICE
A7: CONTRACT NO. HY/2021/06
A8: RETROFITTING OF NOISE BARRIERS ON PO LAM ROAD NORTH AND PO NING ROAD
A10: ACTIVITY SCHEDULE
A12: Schedule No. 13 - Noise Barriers NB09
A14: Item | B14: Activity | J14: Prices (HK$)
A16: 13 | B16: Noise Barriers NB09
A18: 13.1 | B18: Piling Works
A20: 13.1.1 | B20: Establishment of piling plant | J20: $
A22: 13.1.2 | B22: Pre-drilling works | J22: $
A24: 13.1.3 | B24: Piling
A26: 13.1.3.1 | B26: Excavation of piles
A28: 13.1.3.1.1 | B28: Completion of excavation of piles for Bay NB09-01P | J28: $
A29: 13.1.3.1.2 | B29: Completion of excavation of piles for Bay NB09-02P | J29: $
A30: 13.1.3.1.3 | B30: Completion of excavation of piles for Bay NB09-03P | J30: $
A31: 13.1.3.1.4 | B31: Completion of excavation of piles for Bay NB09-04P | J31: $
A34: 13.1.3.2 | B34: Installation of reinforcement for piles
A36: 13.1.3.2.1 | B36: Completion of installation of reinforcement of piles for Bay NB09-01P | J36: $
A37: 13.1.3.2.2 | B37: Completion of installation of reinforcement of piles for Bay NB09-02P | J37: $
A38: 13.1.3.2.3 | B38: Completion of installation of reinforcement of piles for Bay NB09-03P | J38: $
A39: 13.1.3.2.4 | B39: Completion of installation of reinforcement of piles for Bay NB09-04P | J39: $
A42: 13.1.3.3 | B42: Completion of piling works
A44: 13.1.3.3.1 | B44: Completion of all piling works for Bay NB09-01P | J44: $
A45: 13.1.3.3.2 | B45: Completion of all piling works for Bay NB09-02P | J45: $
A46: 13.1.3.3.3 | B46: Completion of all piling works for Bay NB09-03P | J46: $
A47: 13.1.3.3.4 | B47: Completion of all piling works for Bay NB09-04P | J47: $
A50: 13.1.4 | B50: Pile tests
A52: 13.1.4.1 | B52: Completion of all pile tests | J52: $
I76: Total carried to collection | J76: $
A77: Item | B77: Activity | J77: Prices (HK$)
A79: 13.2 | B79: Substructure
A81: 13.2.1 | B81: Excavation for pile cap
A83: 13.2.1.1 | B83: Completion of excavation of pile cap for Bay NB09-01P | J83: $
A84: 13.2.1.2 | B84: Completion of excavation of pile cap for Bay NB09-02P | J84: $
A85: 13.2.1.3 | B85: Completion of excavation of pile cap for Bay NB09-03P | J85: $
A86: 13.2.1.4 | B86: Completion of excavation of pile cap for Bay NB09-04P | J86: $
A89: 13.2.2 | B89: Fixing of reinforcement
A91: 13.2.2.1 | B91: Completion of fixing of reinforcement of pile cap and stem wall for Bay NB09-01P | J91: $
...

Sheet A14
A2: THE GOVERNMENT OF THE HONG KONG SPECIAL ADMINISTRATIVE REGION
A4: HIGHWAYS DEPARTMENT
A5: MAJOR WORKS PROJECT MANAGEMENT OFFICE
A7: CONTRACT NO. HY/2021/06
A8: RETROFITTING OF NOISE BARRIERS ON PO LAM ROAD NORTH AND PO NING ROAD
A10: ACTIVITY SCHEDULE
A12: Schedule No. 14 - Noise Barriers NB10
A14: Item | B14: Activity | J14: Prices (HK$)
A16: 14 | B16: Noise Barriers NB10
A18: 14.1 | B18: Piling Works
A20: 14.1.1 | B20: Establishment of piling plant | J20: $
A22: 14.1.2 | B22: Pre-drilling works | J22: $
A24: 14.1.3 | B24: Piling
A26: 14.1.3.1 | B26: Excavation of piles
A28: 14.1.3.1.1 | B28: Completion of excavation of piles for Bay NB10-01P | J28: $
A29: 14.1.3.1.2 | B29: Completion of excavation of piles for Bay NB10-02P | J29: $
A30: 14.1.3.1.3 | B30: Completion of excavation of piles for Bay NB10-03P | J30: $
A31: 14.1.3.1.4 | B31: Completion of excavation of piles for Bay NB10-04P | J31: $
A34: 14.1.3.2 | B34: Installation of reinforcement for piles
A36: 14.1.3.2.1 | B36: Completion of installation of reinforcement of piles for Bay NB10-01P | J36: $
A37: 14.1.3.2.2 | B37: Completion of installation of reinforcement of piles for Bay NB10-02P | J37: $
A38: 14.1.3.2.3 | B38: Completion of installation of reinforcement of piles for Bay NB10-03P | J38: $
A39: 14.1.3.2.4 | B39: Completion of installation of reinforcement of piles for Bay NB10-04P | J39: $
A42: 14.1.3.3 | B42: Completion of piling works
A44: 14.1.3.3.1 | B44: Completion of all piling works for Bay NB10-01P | J44: $
A45: 14.1.3.3.2 | B45: Completion of all piling works for Bay NB10-02P | J45: $
A46: 14.1.3.3.3 | B46: Completion of all piling works for Bay NB10-03P | J46: $
A47: 14.1.3.3.4 | B47: Completion of all piling works for Bay NB10-04P | J47: $
A50: 14.1.4 | B50: Preliminary Pile
A52: 14.1.4.1 | B52: Completion of one preliminary pile | J52: $
A53: 14.1.4.2 | B53: Completion of all pile tests for preliminary pile | J53: $
I76: Total carried to collection | J76: $
A77: Item | B77: Activity | J77: Prices (HK$)
A79: 14.2 | B79: Substructure
A81: 14.2.1 | B81: Excavation for pile cap
A83: 14.2.1.1 | B83: Completion of excavation of pile cap for Bay NB10-01P | J83: $
A84: 14.2.1.2 | B84: Completion of excavation of pile cap for Bay NB10-02P | J84: $
A85: 14.2.1.3 | B85: Completion of excavation of pile cap for Bay NB10-03P | J85: $
A86: 14.2.1.4 | B86: Completion of excavation of pile cap for Bay NB10-04P | J86: $
A89: 14.2.2 | B89: Fixing of reinforcement
...

Sheet A15
A2: THE GOVERNMENT OF THE HONG KONG SPECIAL ADMINISTRATIVE REGION
A4: HIGHWAYS DEPARTMENT
A5: MAJOR WORKS PROJECT MANAGEMENT OFFICE
A7: CONTRACT NO. HY/2021/06
A8: RETROFITTING OF NOISE BARRIERS ON PO LAM ROAD NORTH AND PO NING ROAD
A10: ACTIVITY SCHEDULE
A12: Schedule No. 15 - Noise Barriers NB11
A14: Item | B14: Activity | J14: Prices (HK$)
A16: 15 | B16: Noise Barriers NB11
A18: 15.1 | B18: Piling Works
A20: 15.1.1 | B20: Establishment of piling plant | J20: $
A22: 15.1.2 | B22: Pre-drilling works | J22: $
A24: 15.1.3 | B24: Piling
A26: 15.1.3.1 | B26: Excavation of piles
A28: 15.1.3.1.1 | B28: Completion of excavation of piles for Bay NB11-01P | J28: $
A29: 15.1.3.1.2 | B29: Completion of excavation of piles for Bay NB11-02P | J29: $
A30: 15.1.3.1.3 | B30: Completion of excavation of piles for Bay NB11-03P | J30: $
A31: 15.1.3.1.4 | B31: Completion of excavation of piles for Bay NB11-04P | J31: $
A32: 15.1.3.1.5 | B32: Completion of excavation of piles for Bay NB11-05P | J32: $
A34: 15.1.3.2 | B34: Installation of reinforcement for piles
A36: 15.1.3.2.1 | B36: Completion of installation of reinforcement of piles for Bay NB11-01P | J36: $
A37: 15.1.3.2.2 | B37: Completion of installation of reinforcement of piles for Bay NB11-02P | J37: $
A38: 15.1.3.2.3 | B38: Completion of installation of reinforcement of piles for Bay NB11-03P | J38: $
A39: 15.1.3.2.4 | B39: Completion of installation of reinforcement of piles for Bay NB11-04P | J39: $
A40: 15.1.3.2.5 | B40: Completion of installation of reinforcement of piles for Bay NB11-05P | J40: $
A42: 15.1.3.3 | B42: Completion of piling works
A44: 15.1.3.3.1 | B44: Completion of all piling works for Bay NB11-01P | J44: $
A45: 15.1.3.3.2 | B45: Completion of all piling works for Bay NB11-02P | J45: $
A46: 15.1.3.3.3 | B46: Completion of all piling works for Bay NB11-03P | J46: $
A47: 15.1.3.3.4 | B47: Completion of all piling works for Bay NB11-04P | J47: $
A48: 15.1.3.3.5 | B48: Completion of all piling works for Bay NB11-05P | J48: $
A50: 15.1.4 | B50: Preliminary Pile
A52: 15.1.4.1 | B52: Completion of one preliminary pile | J52: $
A53: 15.1.4.2 | B53: Completion of all pile tests for preliminary pile | J53: $
I76: Total carried to collection | J76: $
A77: Item | B77: Activity | J77: Prices (HK$)
A79: 15.2 | B79: Substructure
A81: 15.2.1 | B81: Excavation for pile cap
A83: 15.2.1.1 | B83: Completion of excavation of pile cap for Bay NB11-01P | J83: $
A84: 15.2.1.2 | B84: Completion of excavation of pile cap for Bay NB11-02P | J84: $
...

Sheet A16
A2: THE GOVERNMENT OF THE HONG KONG SPECIAL ADMINISTRATIVE REGION
A4: HIGHWAYS DEPARTMENT
A5: MAJOR WORKS PROJECT MANAGEMENT OFFICE
A7: CONTRACT NO. HY/2021/06
A8: RETROFITTING OF NOISE BARRIERS ON PO LAM ROAD NORTH AND PO NING ROAD
A10: ACTIVITY SCHEDULE
A12: Schedule No. 16 - Noise Barriers NB12
A14: Item | B14: Activity | J14: Prices (HK$)
A16: 16 | B16: Noise Barriers NB12
A18: 16.1 | B18: Piling Works
A20: 16.1.1 | B20: Establishment of piling plant | J20: $
A22: 16.1.2 | B22: Pre-drilling works | J22: $
A24: 16.1.3 | B24: Piling
A26: 16.1.3.1 | B26: Excavation of piles
A28: 16.1.3.1.1 | B28: Completion of excavation of piles for Bay NB12-01P | J28: $
A29: 16.1.3.1.2 | B29: Completion of excavation of piles for Bay NB12-02P | J29: $
A30: 16.1.3.1.3 | B30: Completion of excavation of piles for Bay NB12-03P | J30: $
A32: 16.1.3.2 | B32: Installation of reinforcement for piles
A34: 16.1.3.2.1 | B34: Completion of installation of reinforcement of piles for Bay NB12-01P | J34: $
A35: 16.1.3.2.2 | B35: Completion of installation of reinforcement of piles for Bay NB12-02P | J35: $
A36: 16.1.3.2.3 | B36: Completion of installation of reinforcement of piles for Bay NB12-03P | J36: $
A38: 16.1.3.3 | B38: Completion of piling works
A40: 16.1.3.3.1 | B40: Completion of all piling works for Bay NB12-01P | J40: $
A41: 16.1.3.3.2 | B41: Completion of all piling works for Bay NB12-02P | J41: $
A42: 16.1.3.3.3 | B42: Completion of all piling works for Bay NB12-03P | J42: $
I76: Total carried to collection | J76: $
A77: Item | B77: Activity | J77: Prices (HK$)
A79: 16.2 | B79: Substructure
A81: 16.2.1 | B81: Excavation for pile cap
A83: 16.2.1.1 | B83: Completion of excavation of pile cap for Bay NB12-01P | J83: $
A84: 16.2.1.2 | B84: Completion of excavation of pile cap for Bay NB12-02P | J84: $
A85: 16.2.1.3 | B85: Completion of excavation of pile cap for Bay NB12-03P | J85: $
A87: 16.2.2 | B87: Fixing of reinforcement
A89: 16.2.2.1 | B89: Completion of fixing of reinforcement of pile cap and stem wall for Bay NB12-01P | J89: $
A90: 16.2.2.2 | B90: Completion of fixing of reinforcement of pile cap and stem wall for Bay NB12-02P | J90: $
A91: 16.2.2.3 | B91: Completion of fixing of reinforcement of pile cap and stem wall for Bay NB12-03P | J91: $
A93: 16.2.3 | B93: Completion of pile caps with stem wall
A95: 16.2.3.1 | B95: Completion of all pile caps with stem wall and movement joints for Bay NB12-01P | J95: $
A96: 16.2.3.2 | B96: Completion of all pile caps with stem wall and movement joints for Bay NB12-02P | J96: $
A97: 16.2.3.3 | B97: Completion of all pile caps with stem wall and movement joints for Bay NB12-03P | J97: $
...

Sheet A17
A2: THE GOVERNMENT OF THE HONG KONG SPECIAL ADMINISTRATIVE REGION
A4: HIGHWAYS DEPARTMENT
A5: MAJOR WORKS PROJECT MANAGEMENT OFFICE
A7: CONTRACT NO. HY/2021/06
A8: RETROFITTING OF NOISE BARRIERS ON PO LAM ROAD NORTH AND PO NING ROAD
A10: ACTIVITY SCHEDULE
A12: Schedule No. 17 - Noise Barriers NB13
A14: Item | B14: Activity | J14: Prices (HK$)
A16: 17 | B16: Noise Barriers NB13
A18: 17.1 | B18: Piling Works
A20: 17.1.1 | B20: Establishment of piling plant | J20: $
A22: 17.1.2 | B22: Pre-drilling works | J22: $
A24: 17.1.3 | B24: Piling
A26: 17.1.3.1 | B26: Excavation of piles
A28: 17.1.3.1.1 | B28: Completion of excavation of piles for Bay NB13-01P | J28: $
A29: 17.1.3.1.2 | B29: Completion of excavation of piles for Bay NB13-02P | J29: $
A30: 17.1.3.1.3 | B30: Completion of excavation of piles for Bay NB13-03P | J30: $
A33: 17.1.3.2 | B33: Installation of reinforcement for piles
A35: 17.1.3.2.1 | B35: Completion of installation of reinforcement of piles for Bay NB13-01P | J35: $
A36: 17.1.3.2.2 | B36: Completion of installation of reinforcement of piles for Bay NB13-02P | J36: $
A37: 17.1.3.2.3 | B37: Completion of installation of reinforcement of piles for Bay NB13-03P | J37: $
A40: 17.1.3.3 | B40: Completion of piling works
A42: 17.1.3.3.1 | B42: Completion of all piling works for Bay NB13-01P | J42: $
A43: 17.1.3.3.2 | B43: Completion of all piling works for Bay NB13-02P | J43: $
A44: 17.1.3.3.3 | B44: Completion of all piling works for Bay NB13-03P | J44: $
A47: 17.1.4 | B47: Preliminary Pile
A49: 17.1.4.1 | B49: Completion of one preliminary pile | J49: $
A50: 17.1.4.2 | B50: Completion of all pile tests for preliminary pile | J50: $
I76: Total carried to collection | J76: $
A77: Item | B77: Activity | J77: Prices (HK$)
A79: 17.2 | B79: Substructure
A81: 17.2.1 | B81: Excavation for pile cap
A83: 17.2.1.1 | B83: Completion of excavation of pile cap for Bay NB13-01P | J83: $
A84: 17.2.1.2 | B84: Completion of excavation of pile cap for Bay NB13-02P | J84: $
A85: 17.2.1.3 | B85: Completion of excavation of pile cap for Bay NB13-03P | J85: $
A88: 17.2.2 | B88: Fixing of reinforcement
A90: 17.2.2.1 | B90: Completion of fixing of reinforcement of pile cap and stem wall for Bay NB13-01P | J90: $
A91: 17.2.2.2 | B91: Completion of fixing of reinforcement of pile cap and stem wall for Bay NB13-02P | J91: $
A92: 17.2.2.3 | B92: Completion of fixing of reinforcement of pile cap and stem wall for Bay NB13-03P | J92: $
A95: 17.2.3 | B95: Completion of pile caps with stem wall
...

Sheet A18
A2: THE GOVERNMENT OF THE HONG KONG SPECIAL ADMINISTRATIVE REGION
A4: HIGHWAYS DEPARTMENT
A5: MAJOR WORKS PROJECT MANAGEMENT OFFICE
A7: CONTRACT NO. HY/2021/06
A8: RETROFITTING OF NOISE BARRIERS ON PO LAM ROAD NORTH AND PO NING ROAD
A10: ACTIVITY SCHEDULE
A12: Schedule No. 18 - Noise Barriers NB14
A14: Item | B14: Activity | J14: Prices (HK$)
A16: 18 | B16: Noise Barriers NB14
A18: 18.1 | B18: Piling Works
A20: 18.1.1 | B20: Establishment of piling plant | J20: $
A22: 18.1.2 | B22: Pre-drilling works | J22: $
A24: 18.1.3 | B24: Piling
A26: 18.1.3.1 | B26: Excavation of piles
A28: 18.1.3.1.1 | B28: Completion of excavation of piles for Bay NB14-01P | J28: $
A29: 18.1.3.1.2 | B29: Completion of excavation of piles for Bay NB14-02P | J29: $
A30: 18.1.3.1.3 | B30: Completion of excavation of piles for Bay NB14-03P | J30: $
A31: 18.1.3.1.4 | B31: Completion of excavation of piles for Bay NB14-04P | J31: $
A34: 18.1.3.2 | B34: Installation of reinforcement for piles
A36: 18.1.3.2.1 | B36: Completion of installation of reinforcement of piles for Bay NB14-01P | J36: $
A37: 18.1.3.2.2 | B37: Completion of installation of reinforcement of piles for Bay NB14-02P | J37: $
A38: 18.1.3.2.3 | B38: Completion of installation of reinforcement of piles for Bay NB14-03P | J38: $
A39: 18.1.3.2.4 | B39: Completion of installation of reinforcement of piles for Bay NB14-04P | J39: $
A42: 18.1.3.3 | B42: Completion of piling works
A44: 18.1.3.3.1 | B44: Completion of all piling works for Bay NB14-01P | J44: $
A45: 18.1.3.3.2 | B45: Completion of all piling works for Bay NB14-02P | J45: $
A46: 18.1.3.3.3 | B46: Completion of all piling works for Bay NB14-03P | J46: $
A47: 18.1.3.3.4 | B47: Completion of all piling works for Bay NB14-04P | J47: $
I76: Total carried to collection | J76: $
A77: Item | B77: Activity | J77: Prices (HK$)
A79: 18.2 | B79: Substructure
A81: 18.2.1 | B81: Excavation for pile cap
A83: 18.2.1.1 | B83: Completion of excavation of pile cap for Bay NB14-01P | J83: $
A84: 18.2.1.2 | B84: Completion of excavation of pile cap for Bay NB14-02P | J84: $
A85: 18.2.1.3 | B85: Completion of excavation of pile cap for Bay NB14-03P | J85: $
A86: 18.2.1.4 | B86: Completion of excavation of pile cap for Bay NB14-04P | J86: $
A89: 18.2.2 | B89: Fixing of reinforcement
A91: 18.2.2.1 | B91: Completion of fixing of reinforcement of pile cap and stem wall for Bay NB14-01P | J91: $
A92: 18.2.2.2 | B92: Completion of fixing of reinforcement of pile cap and stem wall for Bay NB14-02P | J92: $
A93: 18.2.2.3 | B93: Completion of fixing of reinforcement of pile cap and stem wall for Bay NB14-03P | J93: $
...

Sheet A19
A2: THE GOVERNMENT OF THE HONG KONG SPECIAL ADMINISTRATIVE REGION
A4: HIGHWAYS DEPARTMENT
A5: MAJOR WORKS PROJECT MANAGEMENT OFFICE
A7: CONTRACT NO. HY/2021/06
A8: RETROFITTING OF NOISE BARRIERS ON PO LAM ROAD NORTH AND PO NING ROAD
A10: ACTIVITY SCHEDULE
A12: Schedule No. 19 - Noise Barriers NB15
A14: Item | B14: Activity | J14: Prices (HK$)
A16: 19 | B16: Noise Barriers NB15
A18: 19.1 | B18: Piling Works
A20: 19.1.1 | B20: Establishment of piling plant | J20: $
A22: 19.1.2 | B22: Pre-drilling works | J22: $
A24: 19.1.3 | B24: Piling
A26: 19.1.3.1 | B26: Excavation of piles
A28: 19.1.3.1.1 | B28: Completion of excavation of piles for Bay NB15-01P | J28: $
A29: 19.1.3.1.2 | B29: Completion of excavation of piles for Bay NB15-02P | J29: $
A30: 19.1.3.1.3 | B30: Completion of excavation of piles for Bay NB15-03P | J30: $
A31: 19.1.3.1.4 | B31: Completion of excavation of piles for Bay NB15-04P | J31: $
A32: 19.1.3.1.5 | B32: Completion of excavation of piles for Bay NB15-05P | J32: $
A34: 19.1.3.2 | B34: Installation of reinforcement for piles
A36: 19.1.3.2.1 | B36: Completion of installation of reinforcement of piles for Bay NB15-01P | J36: $
A37: 19.1.3.2.2 | B37: Completion of installation of reinforcement of piles for Bay NB15-02P | J37: $
A38: 19.1.3.2.3 | B38: Completion of installation of reinforcement of piles for Bay NB15-03P | J38: $
A39: 19.1.3.2.4 | B39: Completion of installation of reinforcement of piles for Bay NB15-04P | J39: $
A40: 19.1.3.2.5 | B40: Completion of installation of reinforcement of piles for Bay NB15-05P | J40: $
A42: 19.1.3.3 | B42: Completion of piling works
A44: 19.1.3.3.1 | B44: Completion of all piling works for Bay NB15-01P | J44: $
A45: 19.1.3.3.2 | B45: Completion of all piling works for Bay NB15-02P | J45: $
A46: 19.1.3.3.3 | B46: Completion of all piling works for Bay NB15-03P | J46: $
A47: 19.1.3.3.4 | B47: Completion of all piling works for Bay NB15-04P | J47: $
A48: 19.1.3.3.5 | B48: Completion of all piling works for Bay NB15-05P | J48: $
A50: 19.1.4 | B50: Pile tests
A52: 19.1.4.1 | B52: Completion of all pile tests | J52: $
I76: Total carried to collection | J76: $
A77: Item | B77: Activity | J77: Prices (HK$)
A79: 19.2 | B79: Substructure
A81: 19.2.1 | B81: Excavation for pile cap
A83: 19.2.1.1 | B83: Completion of excavation of pile cap for Bay NB15-01P | J83: $
A84: 19.2.1.2 | B84: Completion of excavation of pile cap for Bay NB15-02P | J84: $
A85: 19.2.1.3 | B85: Completion of excavation of pile cap for Bay NB15-03P | J85: $
...

Sheet A20
A2: THE GOVERNMENT OF THE HONG KONG SPECIAL ADMINISTRATIVE REGION
A4: HIGHWAYS DEPARTMENT
A5: MAJOR WORKS PROJECT MANAGEMENT OFFICE
A7: CONTRACT NO. HY/2021/06
A8: RETROFITTING OF NOISE BARRIERS ON PO LAM ROAD NORTH AND PO NING ROAD
A10: ACTIVITY SCHEDULE
A12: Schedule No. 20 - Noise Barriers NB16
A14: Item | B14: Activity | J14: Prices (HK$)
A16: 20 | B16: Noise Barriers NB16
A18: 20.1 | B18: Piling Works
A20: 20.1.1 | B20: Establishment of piling plant | J20: $
A22: 20.1.2 | B22: Pre-drilling works | J22: $
A24: 20.1.3 | B24: Piling
A26: 20.1.3.1 | B26: Excavation of piles
A28: 20.1.3.1.1 | B28: Completion of excavation of piles for Bay NB16-01P | J28: $
A29: 20.1.3.1.2 | B29: Completion of excavation of piles for Bay NB16-02P | J29: $
A30: 20.1.3.1.3 | B30: Completion of excavation of piles for Bay NB16-03P | J30: $
A31: 20.1.3.1.4 | B31: Completion of excavation of piles for Bay NB16-04P | J31: $
A32: 20.1.3.1.5 | B32: Completion of excavation of piles for Bay NB16-05P | J32: $
A33: 20.1.3.1.6 | B33: Completion of excavation of piles for Bay NB16-06P | J33: $
A34: 20.1.3.1.7 | B34: Completion of excavation of piles for Bay NB16-07P | J34: $
A35: 20.1.3.1.8 | B35: Completion of excavation of piles for Bay NB16-08P | J35: $
A36: 20.1.3.1.9 | B36: Completion of excavation of piles for Bay NB16-09P | J36: $
A37: 20.1.3.1.10 | B37: Completion of excavation of piles for Bay NB16-10P | J37: $
A38: 20.1.3.1.11 | B38: Completion of excavation of piles for Bay NB16-11P | J38: $
A39: 20.1.3.1.12 | B39: Completion of excavation of piles for Bay NB16-12P | J39: $
... A49: 20.1.3.1.22 | B49: Completion of excavation of piles for Bay NB16-22P | J49: $
A51: 20.1.3.2 | B51: Installation of reinforcement for piles
A53: 20.1.3.2.1 | B53: Completion of installation of reinforcement of piles for Bay NB16-01P | J53: $
A54: 20.1.3.2.2 | B54: Completion of installation of reinforcement of piles for Bay NB16-02P | J54: $
A55: 20.1.3.2.3 | B55: Completion of installation of reinforcement of piles for Bay NB16-03P | J55: $
A56: 20.1.3.2.4 | B56: Completion of installation of reinforcement of piles for Bay NB16-04P | J56: $
A57: 20.1.3.2.5 | B57: Completion of installation of reinforcement of piles for Bay NB16-05P | J57: $
A58: 20.1.3.2.6 | B58: Completion of installation of reinforcement of piles for Bay NB16-06P | J58: $
A59: 20.1.3.2.7 | B59: Completion of installation of reinforcement of piles for Bay NB16-07P | J59: $
A60: 20.1.3.2.8 | B60: Completion of installation of reinforcement of piles for Bay NB16-08P | J60: $
A61: 20.1.3.2.9 | B61: Completion of installation of reinforcement of piles for Bay NB16-09P | J61: $
A62: 20.1.3.2.10 | B62: Completion of installation of reinforcement of piles for Bay NB16-10P | J62: $
A63: 20.1.3.2.11 | B63: Completion of installation of reinforcement of piles for Bay NB16-11P | J63: $
A64: 20.1.3.2.12 | B64: Completion of installation of reinforcement of piles for Bay NB16-12P | J64: $
...

Sheet A21
A2: THE GOVERNMENT OF THE HONG KONG SPECIAL ADMINISTRATIVE REGION
A4: HIGHWAYS DEPARTMENT
A5: MAJOR WORKS PROJECT MANAGEMENT OFFICE
A7: CONTRACT NO. HY/2021/06
A8: RETROFITTING OF NOISE BARRIERS ON PO LAM ROAD NORTH AND PO NING ROAD
A10: ACTIVITY SCHEDULE
A12: Schedule No. 21 - Noise Semi-enclosure SE01
A14: Item | B14: Activity | J14: Prices (HK$)
A16: 21 | B16: Noise Semi-enclosure SE01
A18: 21.1 | B18: Piling Works
A20: 21.1.1 | B20: Establishment of piling plant | J20: $
A22: 21.1.2 | B22: Pre-drilling works | J22: $
A24: 21.1.3 | B24: Piling
A26: 21.1.3.1 | B26: Excavation of piles
A28: 21.1.3.1.1 | B28: Completion of excavation of piles for Bay SE01-01P | J28: $
A29: 21.1.3.1.2 | B29: Completion of excavation of piles for Bay SE01-02P | J29: $
A30: 21.1.3.1.3 | B30: Completion of excavation of piles for Bay SE01-03P | J30: $
A31: 21.1.3.1.4 | B31: Completion of excavation of piles for Bay SE01-04P | J31: $
A32: 21.1.3.1.5 | B32: Completion of excavation of piles for Bay SE01-05P | J32: $
A33: 21.1.3.1.6 | B33: Completion of excavation of piles for Bay SE01-101P | J33: $
A34: 21.1.3.1.7 | B34: Completion of excavation of piles for Bay SE01-102P | J34: $
A35: 21.1.3.1.8 | B35: Completion of excavation of piles for Bay SE01-103P | J35: $
A36: 21.1.3.1.9 | B36: Completion of excavation of piles for Bay SE01-104P | J36: $
A37: 21.1.3.1.10 | B37: Completion of excavation of piles for Bay SE01-105P | J37: $
A39: 21.1.3.2 | B39: Installation of reinforcement for piles
A41: 21.1.3.2.1 | B41: Completion of installation of reinforcement of piles for Bay SE01-01P | J41: $
A42: 21.1.3.2.2 | B42: Completion of installation of reinforcement of piles for Bay SE01-02P | J42: $
A43: 21.1.3.2.3 | B43: Completion of installation of reinforcement of piles for Bay SE01-03P | J43: $
A44: 21.1.3.2.4 | B44: Completion of installation of reinforcement of piles for Bay SE01-04P | J44: $
A45: 21.1.3.2.5 | B45: Completion of installation of reinforcement of piles for Bay SE01-05P | J45: $
A46: 21.1.3.2.6 | B46: Completion of installation of reinforcement of piles for Bay SE01-101P | J46: $
A47: 21.1.3.2.7 | B47: Completion of installation of reinforcement of piles for Bay SE01-102P | J47: $
A48: 21.1.3.2.8 | B48: Completion of installation of reinforcement of piles for Bay SE01-103P | J48: $
A49: 21.1.3.2.9 | B49: Completion of installation of reinforcement of piles for Bay SE01-104P | J49: $
A50: 21.1.3.2.10 | B50: Completion of installation of reinforcement of piles for Bay SE01-105P | J50: $
I76: Total carried to collection | J76: $
A77: Item | B77: Activity | J77: Prices (HK$)
A79: 21.1.3.3 | B79: Completion of piling works
A81: 21.1.3.3.1 | B81: Completion of all piling works for Bay SE01-01P | J81: $
A82: 21.1.3.3.2 | B82: Completion of all piling works for Bay SE01-02P | J82: $
...

Sheet A25
A2: THE GOVERNMENT OF THE HONG KONG SPECIAL ADMINISTRATIVE REGION
A4: HIGHWAYS DEPARTMENT
A5: MAJOR WORKS PROJECT MANAGEMENT OFFICE
A7: CONTRACT NO. HY/2021/06
A8: RETROFITTING OF NOISE BARRIERS ON PO LAM ROAD NORTH AND PO NING ROAD
A10: ACTIVITY SCHEDULE
A12: Schedule No. 25 - Geotechnical Works
A14: Item | B14: Activity | J14: Prices (HK$)
A16: 25.1 | B16: Slopeworks
A18: 25.1.1 | B18: Sub-soil drains
A19: 25.1.1.1 | C19: perforated polyethelene pipe; 50mm diameter | J19: $
A21: 25.1.1.2 | C21: UPVC pipe; 50mm diameter | J21: $
A23: 25.1.1.3 | C23: U-channel; 225mm diameter without cover | J23: $
A25: 25.1.1.4 | C25: U-channel; 300mm diameter without cover | J25: $
A27: 25.1.1.5 | C27: U-channel; 375mm diameter without cover | J27: $
A29: 25.1.1.6 | C29: U-channel; 450mm diameter without cover | J29: $
A31: 25.1.1.7 | C31: stepped channel with apron; 300mm diameter | J31: $
A33: 25.1.2 | B33: Granular filters
A34: 25.1.2.1 | C34: grade 75 | J34: $
A36: 25.1.3 | B36: Geotextile filters
A37: 25.1.3.1 | C37: "Miradrain 5000" or product with equivalent performance | J37: $
A39: 25.1.3.2 | C39: non-woven polyprolene | J39: $
A41: 25.1.4 | B41: Earthworks
A42: 25.1.4.1 | C42: general excavation | J42: $
A44: 25.1.4.2 | C44: deposition of general fill material | J44: $
A46: 25.1.4.3 | C46: disposal of material | J46: $
A48: 25.1.4.4 | C48: compaction of general fill material | J48: $
A50: 25.1.5 | B50: Concrete
A51: 25.1.1.1 | C51: no-fines concrete | J51: $
A53: 25.1.6 | B53: Erosion Control Mats | J53: $
A55: 25.1.7 | B55: Wire mesh | J55: $
I76: Total carried to collection | J76: $
A77: Item | B77: Activity | J77: Prices (HK$)
B79: Collection from Page AS.S25/1 | J79: $
I139: Total Prices of Schedule No. 25 Carried to Grand Summary of the Activity Schedule | J139: $
